<?xml version="1.0" encoding="UTF-8"?>
<testng-results skipped="0" failed="1" ignored="0" total="3" passed="2">
  <reporter-output>
  </reporter-output>
  <suite name="Default suite" duration-ms="138" started-at="2019-08-19T11:01:59Z" finished-at="2019-08-19T11:01:59Z">
    <groups>
    </groups>
    <test name="Default test" duration-ms="138" started-at="2019-08-19T11:01:59Z" finished-at="2019-08-19T11:01:59Z">
      <class name="com.model.SoftAssertTest">
        <test-method status="FAIL" signature="Test()[pri:1, instance:com.model.SoftAssertTest@48eff760]" name="Test" duration-ms="30" started-at="2019-08-19T11:01:59Z" finished-at="2019-08-19T11:01:59Z">
          <exception class="java.lang.AssertionError">
            <message>
              <![CDATA[The following asserts failed:
expected [b] but found [a]]]>
            </message>
            <full-stacktrace>
              <![CDATA[java.lang.AssertionError: The following asserts failed:
expected [b] but found [a]
at org.testng.asserts.SoftAssert.assertAll(SoftAssert.java:43)
at com.model.SoftAssertTest.Test(SoftAssertTest.java:19)
at sun.reflect.NativeMethodAccessorImpl.invoke0(Native Method)
at sun.reflect.NativeMethodAccessorImpl.invoke(NativeMethodAccessorImpl.java:62)
at sun.reflect.DelegatingMethodAccessorImpl.invoke(DelegatingMethodAccessorImpl.java:43)
at java.lang.reflect.Method.invoke(Method.java:498)
at org.testng.internal.MethodInvocationHelper.invokeMethod(MethodInvocationHelper.java:124)
at org.testng.internal.Invoker.invokeMethod(Invoker.java:583)
at org.testng.internal.Invoker.invokeTestMethod(Invoker.java:719)
at org.testng.internal.Invoker.invokeTestMethods(Invoker.java:989)
at org.testng.internal.TestMethodWorker.invokeTestMethods(TestMethodWorker.java:125)
at org.testng.internal.TestMethodWorker.run(TestMethodWorker.java:109)
at org.testng.TestRunner.privateRun(TestRunner.java:648)
at org.testng.TestRunner.run(TestRunner.java:505)
at org.testng.SuiteRunner.runTest(SuiteRunner.java:455)
at org.testng.SuiteRunner.runSequentially(SuiteRunner.java:450)
at org.testng.SuiteRunner.privateRun(SuiteRunner.java:415)
at org.testng.SuiteRunner.run(SuiteRunner.java:364)
at org.testng.SuiteRunnerWorker.runSuite(SuiteRunnerWorker.java:52)
at org.testng.SuiteRunnerWorker.run(SuiteRunnerWorker.java:84)
at org.testng.TestNG.runSuitesSequentially(TestNG.java:1208)
at org.testng.TestNG.runSuitesLocally(TestNG.java:1137)
at org.testng.TestNG.runSuites(TestNG.java:1049)
at org.testng.TestNG.run(TestNG.java:1017)
at org.testng.remote.AbstractRemoteTestNG.run(AbstractRemoteTestNG.java:132)
at org.testng.remote.RemoteTestNG.initAndRun(RemoteTestNG.java:230)
at org.testng.remote.RemoteTestNG.main(RemoteTestNG.java:76)
]]>
            </full-stacktrace>
          </exception> <!-- java.lang.AssertionError -->
          <reporter-output>
          </reporter-output>
        </test-method> <!-- Test -->
        <test-method status="PASS" signature="Test1()[pri:2, instance:com.model.SoftAssertTest@48eff760]" name="Test1" duration-ms="17" started-at="2019-08-19T11:01:59Z" finished-at="2019-08-19T11:01:59Z">
          <reporter-output>
          </reporter-output>
        </test-method> <!-- Test1 -->
        <test-method status="PASS" signature="Test2()[pri:3, instance:com.model.SoftAssertTest@48eff760]" name="Test2" duration-ms="17" started-at="2019-08-19T11:01:59Z" finished-at="2019-08-19T11:01:59Z">
          <reporter-output>
          </reporter-output>
        </test-method> <!-- Test2 -->
      </class> <!-- com.model.SoftAssertTest -->
    </test> <!-- Default test -->
  </suite> <!-- Default suite -->
</testng-results>
